[2025-03-10T06:56:32.991+0000] {local_task_job_runner.py:123} INFO - ::group::Pre task execution logs
[2025-03-10T06:56:33.180+0000] {taskinstance.py:2614} INFO - Dependencies all met for dep_context=non-requeueable deps ti=<TaskInstance: validate_all_tables.customers manual__2025-03-10T06:50:39.405277+00:00 [queued]>
[2025-03-10T06:56:34.077+0000] {taskinstance.py:2614} INFO - Dependencies all met for dep_context=requeueable deps ti=<TaskInstance: validate_all_tables.customers manual__2025-03-10T06:50:39.405277+00:00 [queued]>
[2025-03-10T06:56:34.079+0000] {taskinstance.py:2867} INFO - Starting attempt 2 of 2
[2025-03-10T06:56:34.156+0000] {taskinstance.py:2890} INFO - Executing <Task(PythonOperator): customers> on 2025-03-10 06:50:39.405277+00:00
[2025-03-10T06:56:34.178+0000] {warnings.py:112} WARNING - /home/***/.local/lib/python3.12/site-packages/***/task/task_runner/standard_task_runner.py:70: DeprecationWarning: This process (pid=2970) is multi-threaded, use of fork() may lead to deadlocks in the child.
  pid = os.fork()

[2025-03-10T06:56:34.182+0000] {standard_task_runner.py:72} INFO - Started process 2979 to run task
[2025-03-10T06:56:34.187+0000] {standard_task_runner.py:104} INFO - Running: ['***', 'tasks', 'run', 'validate_all_tables', 'customers', 'manual__2025-03-10T06:50:39.405277+00:00', '--job-id', '23', '--raw', '--subdir', 'DAGS_FOLDER/validate_all_tables_dag.py', '--cfg-path', '/tmp/tmpvl7svdbq']
[2025-03-10T06:56:34.207+0000] {standard_task_runner.py:105} INFO - Job 23: Subtask customers
[2025-03-10T06:56:34.539+0000] {task_command.py:467} INFO - Running <TaskInstance: validate_all_tables.customers manual__2025-03-10T06:50:39.405277+00:00 [running]> on host efacfdd0be48
[2025-03-10T06:56:35.266+0000] {taskinstance.py:3134} INFO - Exporting env vars: AIRFLOW_CTX_DAG_OWNER='***' AIRFLOW_CTX_DAG_ID='validate_all_tables' AIRFLOW_CTX_TASK_ID='customers' AIRFLOW_CTX_EXECUTION_DATE='2025-03-10T06:50:39.405277+00:00' AIRFLOW_CTX_TRY_NUMBER='2' AIRFLOW_CTX_DAG_RUN_ID='manual__2025-03-10T06:50:39.405277+00:00'
[2025-03-10T06:56:35.287+0000] {logging_mixin.py:190} INFO - Task instance is in running state
[2025-03-10T06:56:35.312+0000] {logging_mixin.py:190} INFO -  Previous state of the Task instance: queued
[2025-03-10T06:56:35.343+0000] {logging_mixin.py:190} INFO - Current task name:customers state:running start_date:2025-03-10 06:56:33.189440+00:00
[2025-03-10T06:56:35.359+0000] {logging_mixin.py:190} INFO - Dag name:validate_all_tables and current dag run status:running
[2025-03-10T06:56:35.364+0000] {taskinstance.py:732} INFO - ::endgroup::
[2025-03-10T06:56:35.596+0000] {logging_mixin.py:190} INFO - Customers validation failed: Found missing values in customers data
[2025-03-10T06:56:35.640+0000] {taskinstance.py:3313} ERROR - Task failed with exception
Traceback (most recent call last):
  File "/home/airflow/.local/lib/python3.12/site-packages/airflow/models/taskinstance.py", line 768, in _execute_task
    result = _execute_callable(context=context, **execute_callable_kwargs)
             ^^^^^^^^^^^^^^^^^^^^^^^^^^^^^^^^^^^^^^^^^^^^^^^^^^^^^^^^^^^^^
  File "/home/airflow/.local/lib/python3.12/site-packages/airflow/models/taskinstance.py", line 734, in _execute_callable
    return ExecutionCallableRunner(
           ^^^^^^^^^^^^^^^^^^^^^^^^
  File "/home/airflow/.local/lib/python3.12/site-packages/airflow/utils/operator_helpers.py", line 252, in run
    return self.func(*args, **kwargs)
           ^^^^^^^^^^^^^^^^^^^^^^^^^^
  File "/home/airflow/.local/lib/python3.12/site-packages/airflow/models/baseoperator.py", line 424, in wrapper
    return func(self, *args, **kwargs)
           ^^^^^^^^^^^^^^^^^^^^^^^^^^^
  File "/home/airflow/.local/lib/python3.12/site-packages/airflow/operators/python.py", line 238, in execute
    return_value = self.execute_callable()
                   ^^^^^^^^^^^^^^^^^^^^^^^
  File "/home/airflow/.local/lib/python3.12/site-packages/airflow/operators/python.py", line 256, in execute_callable
    return runner.run(*self.op_args, **self.op_kwargs)
           ^^^^^^^^^^^^^^^^^^^^^^^^^^^^^^^^^^^^^^^^^^^
  File "/home/airflow/.local/lib/python3.12/site-packages/airflow/utils/operator_helpers.py", line 252, in run
    return self.func(*args, **kwargs)
           ^^^^^^^^^^^^^^^^^^^^^^^^^^
  File "/opt/airflow/dags/tables_dag.py", line 61, in validate_customers
    raise ValueError('Found missing values in customers data')
ValueError: Found missing values in customers data
[2025-03-10T06:56:35.928+0000] {logging_mixin.py:190} INFO - Task instance in failure state
[2025-03-10T06:56:35.931+0000] {logging_mixin.py:190} INFO - Task start:2025-03-10 06:56:33.189440+00:00 end:2025-03-10 06:56:35.926333+00:00 duration:2.736893
[2025-03-10T06:56:35.944+0000] {logging_mixin.py:190} INFO - Task:<Task(PythonOperator): customers> dag:<DAG: validate_all_tables> dagrun:<DagRun validate_all_tables @ 2025-03-10 06:50:39.405277+00:00: manual__2025-03-10T06:50:39.405277+00:00, state:running, queued_at: 2025-03-10 06:50:39.474775+00:00. externally triggered: True>
[2025-03-10T06:56:35.969+0000] {logging_mixin.py:190} INFO - Failure caused by Found missing values in customers data
[2025-03-10T06:56:35.982+0000] {taskinstance.py:1226} INFO - Marking task as FAILED. dag_id=validate_all_tables, task_id=customers, run_id=manual__2025-03-10T06:50:39.405277+00:00, execution_date=20250310T065039, start_date=20250310T065633, end_date=20250310T065635
[2025-03-10T06:56:36.182+0000] {taskinstance.py:341} INFO - ::group::Post task execution logs
[2025-03-10T06:56:36.195+0000] {standard_task_runner.py:124} ERROR - Failed to execute job 23 for task customers (Found missing values in customers data; 2979)
Traceback (most recent call last):
  File "/home/airflow/.local/lib/python3.12/site-packages/airflow/task/task_runner/standard_task_runner.py", line 117, in _start_by_fork
    ret = args.func(args, dag=self.dag)
          ^^^^^^^^^^^^^^^^^^^^^^^^^^^^^
  File "/home/airflow/.local/lib/python3.12/site-packages/airflow/cli/cli_config.py", line 49, in command
    return func(*args, **kwargs)
           ^^^^^^^^^^^^^^^^^^^^^
  File "/home/airflow/.local/lib/python3.12/site-packages/airflow/utils/cli.py", line 116, in wrapper
    return f(*args, **kwargs)
           ^^^^^^^^^^^^^^^^^^
  File "/home/airflow/.local/lib/python3.12/site-packages/airflow/cli/commands/task_command.py", line 483, in task_run
    task_return_code = _run_task_by_selected_method(args, _dag, ti)
                       ^^^^^^^^^^^^^^^^^^^^^^^^^^^^^^^^^^^^^^^^^^^^
  File "/home/airflow/.local/lib/python3.12/site-packages/airflow/cli/commands/task_command.py", line 256, in _run_task_by_selected_method
    return _run_raw_task(args, ti)
           ^^^^^^^^^^^^^^^^^^^^^^^
  File "/home/airflow/.local/lib/python3.12/site-packages/airflow/cli/commands/task_command.py", line 341, in _run_raw_task
    return ti._run_raw_task(
           ^^^^^^^^^^^^^^^^^
  File "/home/airflow/.local/lib/python3.12/site-packages/airflow/utils/session.py", line 97, in wrapper
    return func(*args, session=session, **kwargs)
           ^^^^^^^^^^^^^^^^^^^^^^^^^^^^^^^^^^^^^^
  File "/home/airflow/.local/lib/python3.12/site-packages/airflow/models/taskinstance.py", line 3006, in _run_raw_task
    return _run_raw_task(
           ^^^^^^^^^^^^^^
  File "/home/airflow/.local/lib/python3.12/site-packages/airflow/models/taskinstance.py", line 274, in _run_raw_task
    TaskInstance._execute_task_with_callbacks(
  File "/home/airflow/.local/lib/python3.12/site-packages/airflow/models/taskinstance.py", line 3161, in _execute_task_with_callbacks
    result = self._execute_task(context, task_orig)
             ^^^^^^^^^^^^^^^^^^^^^^^^^^^^^^^^^^^^^^
  File "/home/airflow/.local/lib/python3.12/site-packages/airflow/models/taskinstance.py", line 3185, in _execute_task
    return _execute_task(self, context, task_orig)
           ^^^^^^^^^^^^^^^^^^^^^^^^^^^^^^^^^^^^^^^
  File "/home/airflow/.local/lib/python3.12/site-packages/airflow/models/taskinstance.py", line 768, in _execute_task
    result = _execute_callable(context=context, **execute_callable_kwargs)
             ^^^^^^^^^^^^^^^^^^^^^^^^^^^^^^^^^^^^^^^^^^^^^^^^^^^^^^^^^^^^^
  File "/home/airflow/.local/lib/python3.12/site-packages/airflow/models/taskinstance.py", line 734, in _execute_callable
    return ExecutionCallableRunner(
           ^^^^^^^^^^^^^^^^^^^^^^^^
  File "/home/airflow/.local/lib/python3.12/site-packages/airflow/utils/operator_helpers.py", line 252, in run
    return self.func(*args, **kwargs)
           ^^^^^^^^^^^^^^^^^^^^^^^^^^
  File "/home/airflow/.local/lib/python3.12/site-packages/airflow/models/baseoperator.py", line 424, in wrapper
    return func(self, *args, **kwargs)
           ^^^^^^^^^^^^^^^^^^^^^^^^^^^
  File "/home/airflow/.local/lib/python3.12/site-packages/airflow/operators/python.py", line 238, in execute
    return_value = self.execute_callable()
                   ^^^^^^^^^^^^^^^^^^^^^^^
  File "/home/airflow/.local/lib/python3.12/site-packages/airflow/operators/python.py", line 256, in execute_callable
    return runner.run(*self.op_args, **self.op_kwargs)
           ^^^^^^^^^^^^^^^^^^^^^^^^^^^^^^^^^^^^^^^^^^^
  File "/home/airflow/.local/lib/python3.12/site-packages/airflow/utils/operator_helpers.py", line 252, in run
    return self.func(*args, **kwargs)
           ^^^^^^^^^^^^^^^^^^^^^^^^^^
  File "/opt/airflow/dags/tables_dag.py", line 61, in validate_customers
    raise ValueError('Found missing values in customers data')
ValueError: Found missing values in customers data
[2025-03-10T06:56:36.326+0000] {local_task_job_runner.py:266} INFO - Task exited with return code 1
[2025-03-10T06:56:36.470+0000] {taskinstance.py:3901} INFO - 0 downstream tasks scheduled from follow-on schedule check
[2025-03-10T06:56:36.514+0000] {local_task_job_runner.py:245} INFO - ::endgroup::
