[2025-03-10T07:27:32.733+0000] {local_task_job_runner.py:123} INFO - ::group::Pre task execution logs
[2025-03-10T07:27:33.617+0000] {taskinstance.py:2614} INFO - Dependencies all met for dep_context=non-requeueable deps ti=<TaskInstance: validate_all_tables.customers manual__2025-03-10T07:27:08.335345+00:00 [queued]>
[2025-03-10T07:27:33.892+0000] {taskinstance.py:2614} INFO - Dependencies all met for dep_context=requeueable deps ti=<TaskInstance: validate_all_tables.customers manual__2025-03-10T07:27:08.335345+00:00 [queued]>
[2025-03-10T07:27:33.908+0000] {taskinstance.py:2867} INFO - Starting attempt 1 of 2
[2025-03-10T07:27:34.105+0000] {taskinstance.py:2890} INFO - Executing <Task(PythonOperator): customers> on 2025-03-10 07:27:08.335345+00:00
[2025-03-10T07:27:34.151+0000] {warnings.py:112} WARNING - /home/***/.local/lib/python3.12/site-packages/***/task/task_runner/standard_task_runner.py:70: DeprecationWarning: This process (pid=3353) is multi-threaded, use of fork() may lead to deadlocks in the child.
  pid = os.fork()

[2025-03-10T07:27:34.154+0000] {standard_task_runner.py:72} INFO - Started process 3369 to run task
[2025-03-10T07:27:34.167+0000] {standard_task_runner.py:104} INFO - Running: ['***', 'tasks', 'run', 'validate_all_tables', 'customers', 'manual__2025-03-10T07:27:08.335345+00:00', '--job-id', '39', '--raw', '--subdir', 'DAGS_FOLDER/validate_all_tables_dag.py', '--cfg-path', '/tmp/tmps9jr02c5']
[2025-03-10T07:27:34.183+0000] {standard_task_runner.py:105} INFO - Job 39: Subtask customers
[2025-03-10T07:27:34.534+0000] {task_command.py:467} INFO - Running <TaskInstance: validate_all_tables.customers manual__2025-03-10T07:27:08.335345+00:00 [running]> on host efacfdd0be48
[2025-03-10T07:27:35.590+0000] {taskinstance.py:3134} INFO - Exporting env vars: AIRFLOW_CTX_DAG_OWNER='***' AIRFLOW_CTX_DAG_ID='validate_all_tables' AIRFLOW_CTX_TASK_ID='customers' AIRFLOW_CTX_EXECUTION_DATE='2025-03-10T07:27:08.335345+00:00' AIRFLOW_CTX_TRY_NUMBER='1' AIRFLOW_CTX_DAG_RUN_ID='manual__2025-03-10T07:27:08.335345+00:00'
[2025-03-10T07:27:35.593+0000] {logging_mixin.py:190} INFO - Task instance is in running state
[2025-03-10T07:27:35.670+0000] {logging_mixin.py:190} INFO -  Previous state of the Task instance: queued
[2025-03-10T07:27:35.680+0000] {logging_mixin.py:190} INFO - Current task name:customers state:running start_date:2025-03-10 07:27:33.646449+00:00
[2025-03-10T07:27:35.684+0000] {logging_mixin.py:190} INFO - Dag name:validate_all_tables and current dag run status:running
[2025-03-10T07:27:35.724+0000] {taskinstance.py:732} INFO - ::endgroup::
[2025-03-10T07:27:35.937+0000] {logging_mixin.py:190} INFO - Customers validation failed: 'phone'
[2025-03-10T07:27:35.940+0000] {taskinstance.py:3313} ERROR - Task failed with exception
Traceback (most recent call last):
  File "/home/airflow/.local/lib/python3.12/site-packages/pandas/core/indexes/base.py", line 3791, in get_loc
    return self._engine.get_loc(casted_key)
           ^^^^^^^^^^^^^^^^^^^^^^^^^^^^^^^^
  File "index.pyx", line 152, in pandas._libs.index.IndexEngine.get_loc
  File "index.pyx", line 181, in pandas._libs.index.IndexEngine.get_loc
  File "pandas/_libs/hashtable_class_helper.pxi", line 7080, in pandas._libs.hashtable.PyObjectHashTable.get_item
  File "pandas/_libs/hashtable_class_helper.pxi", line 7088, in pandas._libs.hashtable.PyObjectHashTable.get_item
KeyError: 'phone'

The above exception was the direct cause of the following exception:

Traceback (most recent call last):
  File "/home/airflow/.local/lib/python3.12/site-packages/airflow/models/taskinstance.py", line 768, in _execute_task
    result = _execute_callable(context=context, **execute_callable_kwargs)
             ^^^^^^^^^^^^^^^^^^^^^^^^^^^^^^^^^^^^^^^^^^^^^^^^^^^^^^^^^^^^^
  File "/home/airflow/.local/lib/python3.12/site-packages/airflow/models/taskinstance.py", line 734, in _execute_callable
    return ExecutionCallableRunner(
           ^^^^^^^^^^^^^^^^^^^^^^^^
  File "/home/airflow/.local/lib/python3.12/site-packages/airflow/utils/operator_helpers.py", line 252, in run
    return self.func(*args, **kwargs)
           ^^^^^^^^^^^^^^^^^^^^^^^^^^
  File "/home/airflow/.local/lib/python3.12/site-packages/airflow/models/baseoperator.py", line 424, in wrapper
    return func(self, *args, **kwargs)
           ^^^^^^^^^^^^^^^^^^^^^^^^^^^
  File "/home/airflow/.local/lib/python3.12/site-packages/airflow/operators/python.py", line 238, in execute
    return_value = self.execute_callable()
                   ^^^^^^^^^^^^^^^^^^^^^^^
  File "/home/airflow/.local/lib/python3.12/site-packages/airflow/operators/python.py", line 256, in execute_callable
    return runner.run(*self.op_args, **self.op_kwargs)
           ^^^^^^^^^^^^^^^^^^^^^^^^^^^^^^^^^^^^^^^^^^^
  File "/home/airflow/.local/lib/python3.12/site-packages/airflow/utils/operator_helpers.py", line 252, in run
    return self.func(*args, **kwargs)
           ^^^^^^^^^^^^^^^^^^^^^^^^^^
  File "/opt/airflow/dags/tables_dag.py", line 87, in validate_customers
    df['phone'] = df['phone'].str.strip()
                  ~~^^^^^^^^^
  File "/home/airflow/.local/lib/python3.12/site-packages/pandas/core/frame.py", line 3893, in __getitem__
    indexer = self.columns.get_loc(key)
              ^^^^^^^^^^^^^^^^^^^^^^^^^
  File "/home/airflow/.local/lib/python3.12/site-packages/pandas/core/indexes/base.py", line 3798, in get_loc
    raise KeyError(key) from err
KeyError: 'phone'
[2025-03-10T07:27:36.155+0000] {logging_mixin.py:190} INFO - Task instance in failure state
[2025-03-10T07:27:36.172+0000] {logging_mixin.py:190} INFO - Task start:2025-03-10 07:27:33.646449+00:00 end:2025-03-10 07:27:36.154002+00:00 duration:2.507553
[2025-03-10T07:27:36.190+0000] {logging_mixin.py:190} INFO - Task:<Task(PythonOperator): customers> dag:<DAG: validate_all_tables> dagrun:<DagRun validate_all_tables @ 2025-03-10 07:27:08.335345+00:00: manual__2025-03-10T07:27:08.335345+00:00, state:running, queued_at: 2025-03-10 07:27:08.358239+00:00. externally triggered: True>
[2025-03-10T07:27:36.199+0000] {logging_mixin.py:190} INFO - Failure caused by 'phone'
[2025-03-10T07:27:36.200+0000] {taskinstance.py:1226} INFO - Marking task as UP_FOR_RETRY. dag_id=validate_all_tables, task_id=customers, run_id=manual__2025-03-10T07:27:08.335345+00:00, execution_date=20250310T072708, start_date=20250310T072733, end_date=20250310T072736
[2025-03-10T07:27:36.429+0000] {taskinstance.py:341} INFO - ::group::Post task execution logs
[2025-03-10T07:27:36.436+0000] {standard_task_runner.py:124} ERROR - Failed to execute job 39 for task customers ('phone'; 3369)
Traceback (most recent call last):
  File "/home/airflow/.local/lib/python3.12/site-packages/pandas/core/indexes/base.py", line 3791, in get_loc
    return self._engine.get_loc(casted_key)
           ^^^^^^^^^^^^^^^^^^^^^^^^^^^^^^^^
  File "index.pyx", line 152, in pandas._libs.index.IndexEngine.get_loc
  File "index.pyx", line 181, in pandas._libs.index.IndexEngine.get_loc
  File "pandas/_libs/hashtable_class_helper.pxi", line 7080, in pandas._libs.hashtable.PyObjectHashTable.get_item
  File "pandas/_libs/hashtable_class_helper.pxi", line 7088, in pandas._libs.hashtable.PyObjectHashTable.get_item
KeyError: 'phone'

The above exception was the direct cause of the following exception:

Traceback (most recent call last):
  File "/home/airflow/.local/lib/python3.12/site-packages/airflow/task/task_runner/standard_task_runner.py", line 117, in _start_by_fork
    ret = args.func(args, dag=self.dag)
          ^^^^^^^^^^^^^^^^^^^^^^^^^^^^^
  File "/home/airflow/.local/lib/python3.12/site-packages/airflow/cli/cli_config.py", line 49, in command
    return func(*args, **kwargs)
           ^^^^^^^^^^^^^^^^^^^^^
  File "/home/airflow/.local/lib/python3.12/site-packages/airflow/utils/cli.py", line 116, in wrapper
    return f(*args, **kwargs)
           ^^^^^^^^^^^^^^^^^^
  File "/home/airflow/.local/lib/python3.12/site-packages/airflow/cli/commands/task_command.py", line 483, in task_run
    task_return_code = _run_task_by_selected_method(args, _dag, ti)
                       ^^^^^^^^^^^^^^^^^^^^^^^^^^^^^^^^^^^^^^^^^^^^
  File "/home/airflow/.local/lib/python3.12/site-packages/airflow/cli/commands/task_command.py", line 256, in _run_task_by_selected_method
    return _run_raw_task(args, ti)
           ^^^^^^^^^^^^^^^^^^^^^^^
  File "/home/airflow/.local/lib/python3.12/site-packages/airflow/cli/commands/task_command.py", line 341, in _run_raw_task
    return ti._run_raw_task(
           ^^^^^^^^^^^^^^^^^
  File "/home/airflow/.local/lib/python3.12/site-packages/airflow/utils/session.py", line 97, in wrapper
    return func(*args, session=session, **kwargs)
           ^^^^^^^^^^^^^^^^^^^^^^^^^^^^^^^^^^^^^^
  File "/home/airflow/.local/lib/python3.12/site-packages/airflow/models/taskinstance.py", line 3006, in _run_raw_task
    return _run_raw_task(
           ^^^^^^^^^^^^^^
  File "/home/airflow/.local/lib/python3.12/site-packages/airflow/models/taskinstance.py", line 274, in _run_raw_task
    TaskInstance._execute_task_with_callbacks(
  File "/home/airflow/.local/lib/python3.12/site-packages/airflow/models/taskinstance.py", line 3161, in _execute_task_with_callbacks
    result = self._execute_task(context, task_orig)
             ^^^^^^^^^^^^^^^^^^^^^^^^^^^^^^^^^^^^^^
  File "/home/airflow/.local/lib/python3.12/site-packages/airflow/models/taskinstance.py", line 3185, in _execute_task
    return _execute_task(self, context, task_orig)
           ^^^^^^^^^^^^^^^^^^^^^^^^^^^^^^^^^^^^^^^
  File "/home/airflow/.local/lib/python3.12/site-packages/airflow/models/taskinstance.py", line 768, in _execute_task
    result = _execute_callable(context=context, **execute_callable_kwargs)
             ^^^^^^^^^^^^^^^^^^^^^^^^^^^^^^^^^^^^^^^^^^^^^^^^^^^^^^^^^^^^^
  File "/home/airflow/.local/lib/python3.12/site-packages/airflow/models/taskinstance.py", line 734, in _execute_callable
    return ExecutionCallableRunner(
           ^^^^^^^^^^^^^^^^^^^^^^^^
  File "/home/airflow/.local/lib/python3.12/site-packages/airflow/utils/operator_helpers.py", line 252, in run
    return self.func(*args, **kwargs)
           ^^^^^^^^^^^^^^^^^^^^^^^^^^
  File "/home/airflow/.local/lib/python3.12/site-packages/airflow/models/baseoperator.py", line 424, in wrapper
    return func(self, *args, **kwargs)
           ^^^^^^^^^^^^^^^^^^^^^^^^^^^
  File "/home/airflow/.local/lib/python3.12/site-packages/airflow/operators/python.py", line 238, in execute
    return_value = self.execute_callable()
                   ^^^^^^^^^^^^^^^^^^^^^^^
  File "/home/airflow/.local/lib/python3.12/site-packages/airflow/operators/python.py", line 256, in execute_callable
    return runner.run(*self.op_args, **self.op_kwargs)
           ^^^^^^^^^^^^^^^^^^^^^^^^^^^^^^^^^^^^^^^^^^^
  File "/home/airflow/.local/lib/python3.12/site-packages/airflow/utils/operator_helpers.py", line 252, in run
    return self.func(*args, **kwargs)
           ^^^^^^^^^^^^^^^^^^^^^^^^^^
  File "/opt/airflow/dags/tables_dag.py", line 87, in validate_customers
    df['phone'] = df['phone'].str.strip()
                  ~~^^^^^^^^^
  File "/home/airflow/.local/lib/python3.12/site-packages/pandas/core/frame.py", line 3893, in __getitem__
    indexer = self.columns.get_loc(key)
              ^^^^^^^^^^^^^^^^^^^^^^^^^
  File "/home/airflow/.local/lib/python3.12/site-packages/pandas/core/indexes/base.py", line 3798, in get_loc
    raise KeyError(key) from err
KeyError: 'phone'
[2025-03-10T07:27:36.533+0000] {local_task_job_runner.py:266} INFO - Task exited with return code 1
[2025-03-10T07:27:36.932+0000] {taskinstance.py:3901} INFO - 0 downstream tasks scheduled from follow-on schedule check
[2025-03-10T07:27:37.004+0000] {local_task_job_runner.py:245} INFO - ::endgroup::
