[2025-03-12T10:00:18.447+0000] {local_task_job_runner.py:123} INFO - ::group::Pre task execution logs
[2025-03-12T10:00:18.583+0000] {taskinstance.py:2614} INFO - Dependencies all met for dep_context=non-requeueable deps ti=<TaskInstance: weekly_category_analysis.brands manual__2025-03-12T10:00:01.174485+00:00 [queued]>
[2025-03-12T10:00:18.658+0000] {taskinstance.py:2614} INFO - Dependencies all met for dep_context=requeueable deps ti=<TaskInstance: weekly_category_analysis.brands manual__2025-03-12T10:00:01.174485+00:00 [queued]>
[2025-03-12T10:00:18.668+0000] {taskinstance.py:2867} INFO - Starting attempt 1 of 2
[2025-03-12T10:00:18.768+0000] {taskinstance.py:2890} INFO - Executing <Task(PythonOperator): brands> on 2025-03-12 10:00:01.174485+00:00
[2025-03-12T10:00:18.806+0000] {warnings.py:112} WARNING - /home/***/.local/lib/python3.12/site-packages/***/task/task_runner/standard_task_runner.py:70: DeprecationWarning: This process (pid=326) is multi-threaded, use of fork() may lead to deadlocks in the child.
  pid = os.fork()

[2025-03-12T10:00:18.805+0000] {standard_task_runner.py:104} INFO - Running: ['***', 'tasks', 'run', 'weekly_category_analysis', 'brands', 'manual__2025-03-12T10:00:01.174485+00:00', '--job-id', '417', '--raw', '--subdir', 'DAGS_FOLDER/s3_data.py', '--cfg-path', '/tmp/tmpupe0a60y']
[2025-03-12T10:00:18.813+0000] {standard_task_runner.py:72} INFO - Started process 346 to run task
[2025-03-12T10:00:18.815+0000] {standard_task_runner.py:105} INFO - Job 417: Subtask brands
[2025-03-12T10:00:19.375+0000] {task_command.py:467} INFO - Running <TaskInstance: weekly_category_analysis.brands manual__2025-03-12T10:00:01.174485+00:00 [running]> on host b404e9833d11
[2025-03-12T10:00:19.980+0000] {taskinstance.py:3134} INFO - Exporting env vars: AIRFLOW_CTX_DAG_OWNER='***' AIRFLOW_CTX_DAG_ID='weekly_category_analysis' AIRFLOW_CTX_TASK_ID='brands' AIRFLOW_CTX_EXECUTION_DATE='2025-03-12T10:00:01.174485+00:00' AIRFLOW_CTX_TRY_NUMBER='1' AIRFLOW_CTX_DAG_RUN_ID='manual__2025-03-12T10:00:01.174485+00:00'
[2025-03-12T10:00:19.997+0000] {logging_mixin.py:190} INFO - Task instance is in running state
[2025-03-12T10:00:19.999+0000] {logging_mixin.py:190} INFO -  Previous state of the Task instance: queued
[2025-03-12T10:00:20.005+0000] {logging_mixin.py:190} INFO - Current task name:brands state:running start_date:2025-03-12 10:00:18.603830+00:00
[2025-03-12T10:00:20.009+0000] {logging_mixin.py:190} INFO - Dag name:weekly_category_analysis and current dag run status:running
[2025-03-12T10:00:20.012+0000] {taskinstance.py:732} INFO - ::endgroup::
[2025-03-12T10:00:20.906+0000] {httpchecksum.py:481} INFO - Skipping checksum validation. Response did not contain one of the following algorithms: ['crc32', 'sha1', 'sha256'].
[2025-03-12T10:00:20.932+0000] {logging_mixin.py:190} INFO - Error reading brands.csv from S3: An error occurred (NoSuchKey) when calling the GetObject operation: The specified key does not exist.
[2025-03-12T10:00:20.942+0000] {logging_mixin.py:190} INFO - Error validating brands: An error occurred (NoSuchKey) when calling the GetObject operation: The specified key does not exist.
[2025-03-12T10:00:20.946+0000] {taskinstance.py:3313} ERROR - Task failed with exception
Traceback (most recent call last):
  File "/home/airflow/.local/lib/python3.12/site-packages/airflow/models/taskinstance.py", line 768, in _execute_task
    result = _execute_callable(context=context, **execute_callable_kwargs)
             ^^^^^^^^^^^^^^^^^^^^^^^^^^^^^^^^^^^^^^^^^^^^^^^^^^^^^^^^^^^^^
  File "/home/airflow/.local/lib/python3.12/site-packages/airflow/models/taskinstance.py", line 734, in _execute_callable
    return ExecutionCallableRunner(
           ^^^^^^^^^^^^^^^^^^^^^^^^
  File "/home/airflow/.local/lib/python3.12/site-packages/airflow/utils/operator_helpers.py", line 252, in run
    return self.func(*args, **kwargs)
           ^^^^^^^^^^^^^^^^^^^^^^^^^^
  File "/home/airflow/.local/lib/python3.12/site-packages/airflow/models/baseoperator.py", line 424, in wrapper
    return func(self, *args, **kwargs)
           ^^^^^^^^^^^^^^^^^^^^^^^^^^^
  File "/home/airflow/.local/lib/python3.12/site-packages/airflow/operators/python.py", line 238, in execute
    return_value = self.execute_callable()
                   ^^^^^^^^^^^^^^^^^^^^^^^
  File "/home/airflow/.local/lib/python3.12/site-packages/airflow/operators/python.py", line 256, in execute_callable
    return runner.run(*self.op_args, **self.op_kwargs)
           ^^^^^^^^^^^^^^^^^^^^^^^^^^^^^^^^^^^^^^^^^^^
  File "/home/airflow/.local/lib/python3.12/site-packages/airflow/utils/operator_helpers.py", line 252, in run
    return self.func(*args, **kwargs)
           ^^^^^^^^^^^^^^^^^^^^^^^^^^
  File "/opt/airflow/dags/validate_all_tables_dag.py", line 222, in validate_brands
    df = read_csv_from_s3(S3_BUCKET, 'brands.csv')
         ^^^^^^^^^^^^^^^^^^^^^^^^^^^^^^^^^^^^^^^^^
  File "/opt/airflow/dags/validate_all_tables_dag.py", line 27, in read_csv_from_s3
    obj = s3_client.get_object(Bucket=bucket, Key=key)
          ^^^^^^^^^^^^^^^^^^^^^^^^^^^^^^^^^^^^^^^^^^^^
  File "/home/airflow/.local/lib/python3.12/site-packages/botocore/client.py", line 569, in _api_call
    return self._make_api_call(operation_name, kwargs)
           ^^^^^^^^^^^^^^^^^^^^^^^^^^^^^^^^^^^^^^^^^^^
  File "/home/airflow/.local/lib/python3.12/site-packages/botocore/client.py", line 1023, in _make_api_call
    raise error_class(parsed_response, operation_name)
botocore.errorfactory.NoSuchKey: An error occurred (NoSuchKey) when calling the GetObject operation: The specified key does not exist.
[2025-03-12T10:00:21.090+0000] {logging_mixin.py:190} INFO - Task instance in failure state
[2025-03-12T10:00:21.169+0000] {logging_mixin.py:190} INFO - Task start:2025-03-12 10:00:18.603830+00:00 end:2025-03-12 10:00:21.085713+00:00 duration:2.481883
[2025-03-12T10:00:21.188+0000] {logging_mixin.py:190} INFO - Task:<Task(PythonOperator): brands> dag:<DAG: weekly_category_analysis> dagrun:<DagRun weekly_category_analysis @ 2025-03-12 10:00:01.174485+00:00: manual__2025-03-12T10:00:01.174485+00:00, state:running, queued_at: 2025-03-12 10:00:01.229393+00:00. externally triggered: True>
[2025-03-12T10:00:21.191+0000] {logging_mixin.py:190} INFO - Failure caused by An error occurred (NoSuchKey) when calling the GetObject operation: The specified key does not exist.
[2025-03-12T10:00:21.199+0000] {taskinstance.py:1226} INFO - Marking task as UP_FOR_RETRY. dag_id=weekly_category_analysis, task_id=brands, run_id=manual__2025-03-12T10:00:01.174485+00:00, execution_date=20250312T100001, start_date=20250312T100018, end_date=20250312T100021
[2025-03-12T10:00:21.437+0000] {taskinstance.py:341} INFO - ::group::Post task execution logs
[2025-03-12T10:00:21.444+0000] {standard_task_runner.py:124} ERROR - Failed to execute job 417 for task brands (An error occurred (NoSuchKey) when calling the GetObject operation: The specified key does not exist.; 346)
Traceback (most recent call last):
  File "/home/airflow/.local/lib/python3.12/site-packages/airflow/task/task_runner/standard_task_runner.py", line 117, in _start_by_fork
    ret = args.func(args, dag=self.dag)
          ^^^^^^^^^^^^^^^^^^^^^^^^^^^^^
  File "/home/airflow/.local/lib/python3.12/site-packages/airflow/cli/cli_config.py", line 49, in command
    return func(*args, **kwargs)
           ^^^^^^^^^^^^^^^^^^^^^
  File "/home/airflow/.local/lib/python3.12/site-packages/airflow/utils/cli.py", line 116, in wrapper
    return f(*args, **kwargs)
           ^^^^^^^^^^^^^^^^^^
  File "/home/airflow/.local/lib/python3.12/site-packages/airflow/cli/commands/task_command.py", line 483, in task_run
    task_return_code = _run_task_by_selected_method(args, _dag, ti)
                       ^^^^^^^^^^^^^^^^^^^^^^^^^^^^^^^^^^^^^^^^^^^^
  File "/home/airflow/.local/lib/python3.12/site-packages/airflow/cli/commands/task_command.py", line 256, in _run_task_by_selected_method
    return _run_raw_task(args, ti)
           ^^^^^^^^^^^^^^^^^^^^^^^
  File "/home/airflow/.local/lib/python3.12/site-packages/airflow/cli/commands/task_command.py", line 341, in _run_raw_task
    return ti._run_raw_task(
           ^^^^^^^^^^^^^^^^^
  File "/home/airflow/.local/lib/python3.12/site-packages/airflow/utils/session.py", line 97, in wrapper
    return func(*args, session=session, **kwargs)
           ^^^^^^^^^^^^^^^^^^^^^^^^^^^^^^^^^^^^^^
  File "/home/airflow/.local/lib/python3.12/site-packages/airflow/models/taskinstance.py", line 3006, in _run_raw_task
    return _run_raw_task(
           ^^^^^^^^^^^^^^
  File "/home/airflow/.local/lib/python3.12/site-packages/airflow/models/taskinstance.py", line 274, in _run_raw_task
    TaskInstance._execute_task_with_callbacks(
  File "/home/airflow/.local/lib/python3.12/site-packages/airflow/models/taskinstance.py", line 3161, in _execute_task_with_callbacks
    result = self._execute_task(context, task_orig)
             ^^^^^^^^^^^^^^^^^^^^^^^^^^^^^^^^^^^^^^
  File "/home/airflow/.local/lib/python3.12/site-packages/airflow/models/taskinstance.py", line 3185, in _execute_task
    return _execute_task(self, context, task_orig)
           ^^^^^^^^^^^^^^^^^^^^^^^^^^^^^^^^^^^^^^^
  File "/home/airflow/.local/lib/python3.12/site-packages/airflow/models/taskinstance.py", line 768, in _execute_task
    result = _execute_callable(context=context, **execute_callable_kwargs)
             ^^^^^^^^^^^^^^^^^^^^^^^^^^^^^^^^^^^^^^^^^^^^^^^^^^^^^^^^^^^^^
  File "/home/airflow/.local/lib/python3.12/site-packages/airflow/models/taskinstance.py", line 734, in _execute_callable
    return ExecutionCallableRunner(
           ^^^^^^^^^^^^^^^^^^^^^^^^
  File "/home/airflow/.local/lib/python3.12/site-packages/airflow/utils/operator_helpers.py", line 252, in run
    return self.func(*args, **kwargs)
           ^^^^^^^^^^^^^^^^^^^^^^^^^^
  File "/home/airflow/.local/lib/python3.12/site-packages/airflow/models/baseoperator.py", line 424, in wrapper
    return func(self, *args, **kwargs)
           ^^^^^^^^^^^^^^^^^^^^^^^^^^^
  File "/home/airflow/.local/lib/python3.12/site-packages/airflow/operators/python.py", line 238, in execute
    return_value = self.execute_callable()
                   ^^^^^^^^^^^^^^^^^^^^^^^
  File "/home/airflow/.local/lib/python3.12/site-packages/airflow/operators/python.py", line 256, in execute_callable
    return runner.run(*self.op_args, **self.op_kwargs)
           ^^^^^^^^^^^^^^^^^^^^^^^^^^^^^^^^^^^^^^^^^^^
  File "/home/airflow/.local/lib/python3.12/site-packages/airflow/utils/operator_helpers.py", line 252, in run
    return self.func(*args, **kwargs)
           ^^^^^^^^^^^^^^^^^^^^^^^^^^
  File "/opt/airflow/dags/validate_all_tables_dag.py", line 222, in validate_brands
    df = read_csv_from_s3(S3_BUCKET, 'brands.csv')
         ^^^^^^^^^^^^^^^^^^^^^^^^^^^^^^^^^^^^^^^^^
  File "/opt/airflow/dags/validate_all_tables_dag.py", line 27, in read_csv_from_s3
    obj = s3_client.get_object(Bucket=bucket, Key=key)
          ^^^^^^^^^^^^^^^^^^^^^^^^^^^^^^^^^^^^^^^^^^^^
  File "/home/airflow/.local/lib/python3.12/site-packages/botocore/client.py", line 569, in _api_call
    return self._make_api_call(operation_name, kwargs)
           ^^^^^^^^^^^^^^^^^^^^^^^^^^^^^^^^^^^^^^^^^^^
  File "/home/airflow/.local/lib/python3.12/site-packages/botocore/client.py", line 1023, in _make_api_call
    raise error_class(parsed_response, operation_name)
botocore.errorfactory.NoSuchKey: An error occurred (NoSuchKey) when calling the GetObject operation: The specified key does not exist.
[2025-03-12T10:00:21.631+0000] {local_task_job_runner.py:266} INFO - Task exited with return code 1
[2025-03-12T10:00:21.935+0000] {taskinstance.py:3901} INFO - 0 downstream tasks scheduled from follow-on schedule check
[2025-03-12T10:00:22.034+0000] {local_task_job_runner.py:245} INFO - ::endgroup::
