[2025-03-10T07:47:14.498+0000] {local_task_job_runner.py:123} INFO - ::group::Pre task execution logs
[2025-03-10T07:47:15.233+0000] {taskinstance.py:2614} INFO - Dependencies all met for dep_context=non-requeueable deps ti=<TaskInstance: validate_all_tables.category_sales_analysis manual__2025-03-10T07:45:56.588478+00:00 [queued]>
[2025-03-10T07:47:15.299+0000] {taskinstance.py:2614} INFO - Dependencies all met for dep_context=requeueable deps ti=<TaskInstance: validate_all_tables.category_sales_analysis manual__2025-03-10T07:45:56.588478+00:00 [queued]>
[2025-03-10T07:47:15.301+0000] {taskinstance.py:2867} INFO - Starting attempt 1 of 2
[2025-03-10T07:47:15.368+0000] {taskinstance.py:2890} INFO - Executing <Task(PythonOperator): category_sales_analysis> on 2025-03-10 07:45:56.588478+00:00
[2025-03-10T07:47:15.391+0000] {warnings.py:112} WARNING - /home/***/.local/lib/python3.12/site-packages/***/task/task_runner/standard_task_runner.py:70: DeprecationWarning: This process (pid=3752) is multi-threaded, use of fork() may lead to deadlocks in the child.
  pid = os.fork()

[2025-03-10T07:47:15.395+0000] {standard_task_runner.py:72} INFO - Started process 3754 to run task
[2025-03-10T07:47:15.399+0000] {standard_task_runner.py:104} INFO - Running: ['***', 'tasks', 'run', 'validate_all_tables', 'category_sales_analysis', 'manual__2025-03-10T07:45:56.588478+00:00', '--job-id', '88', '--raw', '--subdir', 'DAGS_FOLDER/validate_all_tables_dag.py', '--cfg-path', '/tmp/tmpv0funecp']
[2025-03-10T07:47:15.410+0000] {standard_task_runner.py:105} INFO - Job 88: Subtask category_sales_analysis
[2025-03-10T07:47:15.597+0000] {task_command.py:467} INFO - Running <TaskInstance: validate_all_tables.category_sales_analysis manual__2025-03-10T07:45:56.588478+00:00 [running]> on host efacfdd0be48
[2025-03-10T07:47:16.080+0000] {taskinstance.py:3134} INFO - Exporting env vars: AIRFLOW_CTX_DAG_OWNER='***' AIRFLOW_CTX_DAG_ID='validate_all_tables' AIRFLOW_CTX_TASK_ID='category_sales_analysis' AIRFLOW_CTX_EXECUTION_DATE='2025-03-10T07:45:56.588478+00:00' AIRFLOW_CTX_TRY_NUMBER='1' AIRFLOW_CTX_DAG_RUN_ID='manual__2025-03-10T07:45:56.588478+00:00'
[2025-03-10T07:47:16.088+0000] {logging_mixin.py:190} INFO - Task instance is in running state
[2025-03-10T07:47:16.090+0000] {logging_mixin.py:190} INFO -  Previous state of the Task instance: queued
[2025-03-10T07:47:16.091+0000] {logging_mixin.py:190} INFO - Current task name:category_sales_analysis state:running start_date:2025-03-10 07:47:15.235559+00:00
[2025-03-10T07:47:16.093+0000] {logging_mixin.py:190} INFO - Dag name:validate_all_tables and current dag run status:running
[2025-03-10T07:47:16.094+0000] {taskinstance.py:732} INFO - ::endgroup::
[2025-03-10T07:47:16.209+0000] {logging_mixin.py:190} INFO - Category sales analysis failed: "Column(s) ['list_price'] do not exist"
[2025-03-10T07:47:16.223+0000] {taskinstance.py:3313} ERROR - Task failed with exception
Traceback (most recent call last):
  File "/home/airflow/.local/lib/python3.12/site-packages/airflow/models/taskinstance.py", line 768, in _execute_task
    result = _execute_callable(context=context, **execute_callable_kwargs)
             ^^^^^^^^^^^^^^^^^^^^^^^^^^^^^^^^^^^^^^^^^^^^^^^^^^^^^^^^^^^^^
  File "/home/airflow/.local/lib/python3.12/site-packages/airflow/models/taskinstance.py", line 734, in _execute_callable
    return ExecutionCallableRunner(
           ^^^^^^^^^^^^^^^^^^^^^^^^
  File "/home/airflow/.local/lib/python3.12/site-packages/airflow/utils/operator_helpers.py", line 252, in run
    return self.func(*args, **kwargs)
           ^^^^^^^^^^^^^^^^^^^^^^^^^^
  File "/home/airflow/.local/lib/python3.12/site-packages/airflow/models/baseoperator.py", line 424, in wrapper
    return func(self, *args, **kwargs)
           ^^^^^^^^^^^^^^^^^^^^^^^^^^^
  File "/home/airflow/.local/lib/python3.12/site-packages/airflow/operators/python.py", line 238, in execute
    return_value = self.execute_callable()
                   ^^^^^^^^^^^^^^^^^^^^^^^
  File "/home/airflow/.local/lib/python3.12/site-packages/airflow/operators/python.py", line 256, in execute_callable
    return runner.run(*self.op_args, **self.op_kwargs)
           ^^^^^^^^^^^^^^^^^^^^^^^^^^^^^^^^^^^^^^^^^^^
  File "/home/airflow/.local/lib/python3.12/site-packages/airflow/utils/operator_helpers.py", line 252, in run
    return self.func(*args, **kwargs)
           ^^^^^^^^^^^^^^^^^^^^^^^^^^
  File "/opt/airflow/dags/validate_all_tables_dag.py", line 30, in analyze_category_sales
    category_sales = sales_data.groupby('category_name').agg({
                     ^^^^^^^^^^^^^^^^^^^^^^^^^^^^^^^^^^^^^^^^^
  File "/home/airflow/.local/lib/python3.12/site-packages/pandas/core/groupby/generic.py", line 1445, in aggregate
    result = op.agg()
             ^^^^^^^^
  File "/home/airflow/.local/lib/python3.12/site-packages/pandas/core/apply.py", line 175, in agg
    return self.agg_dict_like()
           ^^^^^^^^^^^^^^^^^^^^
  File "/home/airflow/.local/lib/python3.12/site-packages/pandas/core/apply.py", line 406, in agg_dict_like
    return self.agg_or_apply_dict_like(op_name="agg")
           ^^^^^^^^^^^^^^^^^^^^^^^^^^^^^^^^^^^^^^^^^^
  File "/home/airflow/.local/lib/python3.12/site-packages/pandas/core/apply.py", line 1390, in agg_or_apply_dict_like
    result_index, result_data = self.compute_dict_like(
                                ^^^^^^^^^^^^^^^^^^^^^^^
  File "/home/airflow/.local/lib/python3.12/site-packages/pandas/core/apply.py", line 445, in compute_dict_like
    func = self.normalize_dictlike_arg(op_name, selected_obj, func)
           ^^^^^^^^^^^^^^^^^^^^^^^^^^^^^^^^^^^^^^^^^^^^^^^^^^^^^^^^
  File "/home/airflow/.local/lib/python3.12/site-packages/pandas/core/apply.py", line 639, in normalize_dictlike_arg
    raise KeyError(f"Column(s) {list(cols)} do not exist")
KeyError: "Column(s) ['list_price'] do not exist"
[2025-03-10T07:47:16.329+0000] {logging_mixin.py:190} INFO - Task instance in failure state
[2025-03-10T07:47:16.334+0000] {logging_mixin.py:190} INFO - Task start:2025-03-10 07:47:15.235559+00:00 end:2025-03-10 07:47:16.328104+00:00 duration:1.092545
[2025-03-10T07:47:16.339+0000] {logging_mixin.py:190} INFO - Task:<Task(PythonOperator): category_sales_analysis> dag:<DAG: validate_all_tables> dagrun:<DagRun validate_all_tables @ 2025-03-10 07:45:56.588478+00:00: manual__2025-03-10T07:45:56.588478+00:00, state:running, queued_at: 2025-03-10 07:45:56.624341+00:00. externally triggered: True>
[2025-03-10T07:47:16.340+0000] {logging_mixin.py:190} INFO - Failure caused by "Column(s) ['list_price'] do not exist"
[2025-03-10T07:47:16.342+0000] {taskinstance.py:1226} INFO - Marking task as UP_FOR_RETRY. dag_id=validate_all_tables, task_id=category_sales_analysis, run_id=manual__2025-03-10T07:45:56.588478+00:00, execution_date=20250310T074556, start_date=20250310T074715, end_date=20250310T074716
[2025-03-10T07:47:16.419+0000] {taskinstance.py:341} INFO - ::group::Post task execution logs
[2025-03-10T07:47:16.421+0000] {standard_task_runner.py:124} ERROR - Failed to execute job 88 for task category_sales_analysis ("Column(s) ['list_price'] do not exist"; 3754)
Traceback (most recent call last):
  File "/home/airflow/.local/lib/python3.12/site-packages/airflow/task/task_runner/standard_task_runner.py", line 117, in _start_by_fork
    ret = args.func(args, dag=self.dag)
          ^^^^^^^^^^^^^^^^^^^^^^^^^^^^^
  File "/home/airflow/.local/lib/python3.12/site-packages/airflow/cli/cli_config.py", line 49, in command
    return func(*args, **kwargs)
           ^^^^^^^^^^^^^^^^^^^^^
  File "/home/airflow/.local/lib/python3.12/site-packages/airflow/utils/cli.py", line 116, in wrapper
    return f(*args, **kwargs)
           ^^^^^^^^^^^^^^^^^^
  File "/home/airflow/.local/lib/python3.12/site-packages/airflow/cli/commands/task_command.py", line 483, in task_run
    task_return_code = _run_task_by_selected_method(args, _dag, ti)
                       ^^^^^^^^^^^^^^^^^^^^^^^^^^^^^^^^^^^^^^^^^^^^
  File "/home/airflow/.local/lib/python3.12/site-packages/airflow/cli/commands/task_command.py", line 256, in _run_task_by_selected_method
    return _run_raw_task(args, ti)
           ^^^^^^^^^^^^^^^^^^^^^^^
  File "/home/airflow/.local/lib/python3.12/site-packages/airflow/cli/commands/task_command.py", line 341, in _run_raw_task
    return ti._run_raw_task(
           ^^^^^^^^^^^^^^^^^
  File "/home/airflow/.local/lib/python3.12/site-packages/airflow/utils/session.py", line 97, in wrapper
    return func(*args, session=session, **kwargs)
           ^^^^^^^^^^^^^^^^^^^^^^^^^^^^^^^^^^^^^^
  File "/home/airflow/.local/lib/python3.12/site-packages/airflow/models/taskinstance.py", line 3006, in _run_raw_task
    return _run_raw_task(
           ^^^^^^^^^^^^^^
  File "/home/airflow/.local/lib/python3.12/site-packages/airflow/models/taskinstance.py", line 274, in _run_raw_task
    TaskInstance._execute_task_with_callbacks(
  File "/home/airflow/.local/lib/python3.12/site-packages/airflow/models/taskinstance.py", line 3161, in _execute_task_with_callbacks
    result = self._execute_task(context, task_orig)
             ^^^^^^^^^^^^^^^^^^^^^^^^^^^^^^^^^^^^^^
  File "/home/airflow/.local/lib/python3.12/site-packages/airflow/models/taskinstance.py", line 3185, in _execute_task
    return _execute_task(self, context, task_orig)
           ^^^^^^^^^^^^^^^^^^^^^^^^^^^^^^^^^^^^^^^
  File "/home/airflow/.local/lib/python3.12/site-packages/airflow/models/taskinstance.py", line 768, in _execute_task
    result = _execute_callable(context=context, **execute_callable_kwargs)
             ^^^^^^^^^^^^^^^^^^^^^^^^^^^^^^^^^^^^^^^^^^^^^^^^^^^^^^^^^^^^^
  File "/home/airflow/.local/lib/python3.12/site-packages/airflow/models/taskinstance.py", line 734, in _execute_callable
    return ExecutionCallableRunner(
           ^^^^^^^^^^^^^^^^^^^^^^^^
  File "/home/airflow/.local/lib/python3.12/site-packages/airflow/utils/operator_helpers.py", line 252, in run
    return self.func(*args, **kwargs)
           ^^^^^^^^^^^^^^^^^^^^^^^^^^
  File "/home/airflow/.local/lib/python3.12/site-packages/airflow/models/baseoperator.py", line 424, in wrapper
    return func(self, *args, **kwargs)
           ^^^^^^^^^^^^^^^^^^^^^^^^^^^
  File "/home/airflow/.local/lib/python3.12/site-packages/airflow/operators/python.py", line 238, in execute
    return_value = self.execute_callable()
                   ^^^^^^^^^^^^^^^^^^^^^^^
  File "/home/airflow/.local/lib/python3.12/site-packages/airflow/operators/python.py", line 256, in execute_callable
    return runner.run(*self.op_args, **self.op_kwargs)
           ^^^^^^^^^^^^^^^^^^^^^^^^^^^^^^^^^^^^^^^^^^^
  File "/home/airflow/.local/lib/python3.12/site-packages/airflow/utils/operator_helpers.py", line 252, in run
    return self.func(*args, **kwargs)
           ^^^^^^^^^^^^^^^^^^^^^^^^^^
  File "/opt/airflow/dags/validate_all_tables_dag.py", line 30, in analyze_category_sales
    category_sales = sales_data.groupby('category_name').agg({
                     ^^^^^^^^^^^^^^^^^^^^^^^^^^^^^^^^^^^^^^^^^
  File "/home/airflow/.local/lib/python3.12/site-packages/pandas/core/groupby/generic.py", line 1445, in aggregate
    result = op.agg()
             ^^^^^^^^
  File "/home/airflow/.local/lib/python3.12/site-packages/pandas/core/apply.py", line 175, in agg
    return self.agg_dict_like()
           ^^^^^^^^^^^^^^^^^^^^
  File "/home/airflow/.local/lib/python3.12/site-packages/pandas/core/apply.py", line 406, in agg_dict_like
    return self.agg_or_apply_dict_like(op_name="agg")
           ^^^^^^^^^^^^^^^^^^^^^^^^^^^^^^^^^^^^^^^^^^
  File "/home/airflow/.local/lib/python3.12/site-packages/pandas/core/apply.py", line 1390, in agg_or_apply_dict_like
    result_index, result_data = self.compute_dict_like(
                                ^^^^^^^^^^^^^^^^^^^^^^^
  File "/home/airflow/.local/lib/python3.12/site-packages/pandas/core/apply.py", line 445, in compute_dict_like
    func = self.normalize_dictlike_arg(op_name, selected_obj, func)
           ^^^^^^^^^^^^^^^^^^^^^^^^^^^^^^^^^^^^^^^^^^^^^^^^^^^^^^^^
  File "/home/airflow/.local/lib/python3.12/site-packages/pandas/core/apply.py", line 639, in normalize_dictlike_arg
    raise KeyError(f"Column(s) {list(cols)} do not exist")
KeyError: "Column(s) ['list_price'] do not exist"
[2025-03-10T07:47:16.496+0000] {local_task_job_runner.py:266} INFO - Task exited with return code 1
[2025-03-10T07:47:16.582+0000] {taskinstance.py:3901} INFO - 0 downstream tasks scheduled from follow-on schedule check
[2025-03-10T07:47:16.590+0000] {local_task_job_runner.py:245} INFO - ::endgroup::
